Workbook

Sheet 00_模板说明
A1: 化妆品成分 4库筛查输出模板
A3: 用途
A4: 该模板用于承接客户成分清单，经 4 个数据库筛查后输出单一成分级结果，并在配方级给出汇总。
A6: 本模板已结合当前 6 个附件的字段结构设计：
A7: 1) CA Hotlist Prohibited：输出禁用命中、CAS、同义词/相关化合物
A8: 2) CA Hotlist Restricted：输出限用命中、使用条件/部位、最大允许浓度、Warning statement
A9: 3) CIR Quick Reference：输出 Finding 和 Conclusion
A10: 4) CFR 禁用物质：输出美国联邦禁用命中
A11: 5) 客户成分表：兼容“一个表一个配方”和“一个表多个同基础配方”两种结构
A12: 6) 预留模糊匹配日志：用于后续 Python + AI 候选匹配与人工复核
A14: 建议工作流
A15: Step 1：将客户原始成分整合到“02_客户成分汇总”
... A32: SAH157 | SAH157 - VITAMIN C | HAND CREAM

Sheet 01_字段映射
A1: Source File | B1: Source Sheet | C1: Source Column(s) | D1: Output Sheet | E1: Output Column Group | F1: Key Output Fields | G1: Usage Note
A2: CA Hotlist Prohibited.xlsx | B2: Sheet1 | C2: Ingredient / CAS / Synonyms and Related Compounds | D2: 03_筛查输出模板 | E2: CA Prohibited | F2: CA Prohibited Hit; Matched Ingredient; CAS; Synonyms; Evidence | G2: 加拿大禁用，命中后通常为硬性阻断
A3: CA Hotlist Restricted.xlsx | B3: Sheet1 | C3: Chemical / CAS / Synonyms / Conditions of Use / Maximum Concentration / Warnings | D3: 03_筛查输出模板 | E3: CA Restricted | F3: CA Restricted Hit; Matched Ingredient; CAS; Conditions of Use / Allowed Body Site; Max Conc.; Warning Statement; Assessment Note | G3: 重点关注允许添加部位、限量、warning statement
A4: CIR_Quick_Reference_Table 2025.xlsx | B4: Updated_Master | C4: Ingredient / Finding / Conclusion | D4: 03_筛查输出模板 | E4: CIR | F4: CIR Hit; Matched Ingredient; Finding; Conclusion; Interpretation | G4: CIR 为美国安全评估参考，不等同法规禁限用
A5: CFR禁用物质.xlsx | B5: Sheet1 | C5: Prohibited substance term | D5: 03_筛查输出模板 | E5: CFR | F5: CFR Hit; Matched Substance; Evidence | G5: 美国联邦禁用少量物质，命中后通常为硬性阻断
A6: HA440 INGREDIENTS for Sugar Pop Facial Mask – Cake.xlsx | B6: FACIAL MASK - CAKE | C6: No. / CTFA INCI Name / CAS No / W/W% | D6: 02_客户成分汇总 & 03_筛查输出模板 | E6: Client Input | F6: Formula Code; Formula Name; Ingredient No; Raw INCI; CAS; W/W% | G6: 一个表一个配方
A7: SAH155 & SAH157 INGREDIENTS for Cat Pop Hand Cream.xlsx | B7: HAND CREAM | C7: No. / CTFA INCI Name / CAS No / SAH155 / SAH157 | D7: 02_客户成分汇总 & 03_筛查输出模板 | E7: Client Input | F7: Formula Code; Formula Name; Ingredient No; Raw INCI; CAS; W/W% | G7: 一个表多个同基础配方，按配方拆成多行

Sheet 02_客户成分汇总
A1: Record ID | B1: Client File | C1: Source Sheet | D1: Formula Code | E1: Formula Name | F1: Product Family | G1: Ingredient No | H1: Raw INCI Name | I1: Raw CAS No | J1: Input W/W % | K1: Variant Group
A2: 1 | B2: HA440 INGREDIENTS for Sugar Pop Facial Mask – Cake.xlsx | C2: FACIAL MASK - CAKE | D2: HA440 | E2: FACIAL MASK - CAKE | F2: FACIAL MASK - CAKE | G2: 1 | H2: WATER | I2: 7732-18-5 | J2: 90.605 | K2: HA440
A3: 2 | B3: HA440 INGREDIENTS for Sugar Pop Facial Mask – Cake.xlsx | C3: FACIAL MASK - CAKE | D3: HA440 | E3: FACIAL MASK - CAKE | F3: FACIAL MASK - CAKE | G3: 2 | H3: PROPYLENE GLYCOL | I3: 57-55-6 | J3: 4.348 | K3: HA440
A4: 3 | B4: HA440 INGREDIENTS for Sugar Pop Facial Mask – Cake.xlsx | C4: FACIAL MASK - CAKE | D4: HA440 | E4: FACIAL MASK - CAKE | F4: FACIAL MASK - CAKE | G4: 3 | H4: GLYCERIN | I4: 56-81-5 | J4: 4 | K4: HA440
A5: 4 | B5: HA440 INGREDIENTS for Sugar Pop Facial Mask – Cake.xlsx | C5: FACIAL MASK - CAKE | D5: HA440 | E5: FACIAL MASK - CAKE | F5: FACIAL MASK - CAKE | G5: 4 | H5: HYDROXYACETOPHENONE | I5: 99-93-4 | J5: 0.4 | K5: HA440
A6: 5 | B6: HA440 INGREDIENTS for Sugar Pop Facial Mask – Cake.xlsx | C6: FACIAL MASK - CAKE | D6: HA440 | E6: FACIAL MASK - CAKE | F6: FACIAL MASK - CAKE | G6: 5 | H6: ALLANTOIN | I6: 97-59-6 | J6: 0.2 | K6: HA440
A7: 6 | B7: HA440 INGREDIENTS for Sugar Pop Facial Mask – Cake.xlsx | C7: FACIAL MASK - CAKE | D7: HA440 | E7: FACIAL MASK - CAKE | F7: FACIAL MASK - CAKE | G7: 6 | H7: HYDROXYETHYLCELLULOSE | I7: 9004-62-0 | J7: 0.1978 | K7: HA440
A8: 7 | B8: HA440 INGREDIENTS for Sugar Pop Facial Mask – Cake.xlsx | C8: FACIAL MASK - CAKE | D8: HA440 | E8: FACIAL MASK - CAKE | F8: FACIAL MASK - CAKE | G8: 7 | H8: CARBOMER | I8: 9007-20-9 | J8: 0.08 | K8: HA440
A9: 8 | B9: HA440 INGREDIENTS for Sugar Pop Facial Mask – Cake.xlsx | C9: FACIAL MASK - CAKE | D9: HA440 | E9: FACIAL MASK - CAKE | F9: FACIAL MASK - CAKE | G9: 8 | H9: TRIETHANOLAMINE | I9: 102-71-6 | J9: 0.08 | K9: HA440
A10: 9 | B10: HA440 INGREDIENTS for Sugar Pop Facial Mask – Cake.xlsx | C10: FACIAL MASK - CAKE | D10: HA440 | E10: FACIAL MASK - CAKE | F10: FACIAL MASK - CAKE | G10: 9 | H10: CAPRYLHYDROXAMIC ACID | J10: 0.048 | K10: HA440
A11: 10 | B11: HA440 INGREDIENTS for Sugar Pop Facial Mask – Cake.xlsx | C11: FACIAL MASK - CAKE | D11: HA440 | E11: FACIAL MASK - CAKE | F11: FACIAL MASK - CAKE | G11: 10 | H11: DISODIUM EDTA | I11: 139-33-3 | J11: 0.03 | K11: HA440
A12: 11 | B12: HA440 INGREDIENTS for Sugar Pop Facial Mask – Cake.xlsx | C12: FACIAL MASK - CAKE | D12: HA440 | E12: FACIAL MASK - CAKE | F12: FACIAL MASK - CAKE | G12: 11 | H12: GLYCERYL CAPRYLATE | I12: 26402-26-6 | J12: 0.004 | K12: HA440
A13: 12 | B13: HA440 INGREDIENTS for Sugar Pop Facial Mask – Cake.xlsx | C13: FACIAL MASK - CAKE | D13: HA440 | E13: FACIAL MASK - CAKE | F13: FACIAL MASK - CAKE | G13: 12 | H13: PEG-40 HYDROGENATED CASTOR OIL | I13: 61788-85-0 | J13: 0.0036 | K13: HA440
A14: 13 | B14: HA440 INGREDIENTS for Sugar Pop Facial Mask – Cake.xlsx | C14: FACIAL MASK - CAKE | D14: HA440 | E14: FACIAL MASK - CAKE | F14: FACIAL MASK - CAKE | G14: 13 | H14: FRAGRANCE | J14: 0.001 | K14: HA440
A15: 14 | B15: HA440 INGREDIENTS for Sugar Pop Facial Mask – Cake.xlsx | C15: FACIAL MASK - CAKE | D15: HA440 | E15: FACIAL MASK - CAKE | F15: FACIAL MASK - CAKE | G15: 14 | H15: POLYSORBATE 60 | I15: 9005-67-8 | J15: 0.001 | K15: HA440
A16: 15 | B16: HA440 INGREDIENTS for Sugar Pop Facial Mask – Cake.xlsx | C16: FACIAL MASK - CAKE | D16: HA440 | E16: FACIAL MASK - CAKE | F16: FACIAL MASK - CAKE | G16: 15 | H16: DISODIUM PHOSPHATE | I16: 7558-79-4 | J16: 0.001 | K16: HA440
A17: 16 | B17: HA440 INGREDIENTS for Sugar Pop Facial Mask – Cake.xlsx | C17: FACIAL MASK - CAKE | D17: HA440 | E17: FACIAL MASK - CAKE | F17: FACIAL MASK - CAKE | G17: 16 | H17: PEG-10 | I17: 5579-66-8/25322-68-3 | J17: 0.0004 | K17: HA440
A18: 17 | B18: HA440 INGREDIENTS for Sugar Pop Facial Mask – Cake.xlsx | C18: FACIAL MASK - CAKE | D18: HA440 | E18: FACIAL MASK - CAKE | F18: FACIAL MASK - CAKE | G18: 17 | H18: SODIUM PHOSPHATE | I18: 7558-80-7 | J18: 0.0002 | K18: HA440
A19: 18 | B19: SAH155 & SAH157 INGREDIENTS for Cat Pop Hand Cream.xlsx | C19: HAND CREAM | D19: SAH155 | E19: SAH155 - PEACH | F19: HAND CREAM | G19: 1 | H19: WATER | I19: 7732-18-5 | J19: 91.34 | K19: SAH155
A20: 19 | B20: SAH155 & SAH157 INGREDIENTS for Cat Pop Hand Cream.xlsx | C20: HAND CREAM | D20: SAH155 | E20: SAH155 - PEACH | F20: HAND CREAM | G20: 2 | H20: MINERAL OIL | I20: 8012-95-1;8020-83-5;8042-47-5 | J20: 3 | K20: SAH155
A21: 20 | B21: SAH155 & SAH157 INGREDIENTS for Cat Pop Hand Cream.xlsx | C21: HAND CREAM | D21: SAH155 | E21: SAH155 - PEACH | F21: HAND CREAM | G21: 3 | H21: PETROLATUM | I21: 8009-03-8 | J21: 2 | K21: SAH155
A22: 21 | B22: SAH155 & SAH157 INGREDIENTS for Cat Pop Hand Cream.xlsx | C22: HAND CREAM | D22: SAH155 | E22: SAH155 - PEACH | F22: HAND CREAM | G22: 4 | H22: CETEARYL ALCOHOL | I22: 8005-44-5;67762-27-0 | J22: 1.2 | K22: SAH155
A23: 22 | B23: SAH155 & SAH157 INGREDIENTS for Cat Pop Hand Cream.xlsx | C23: HAND CREAM | D23: SAH155 | E23: SAH155 - PEACH | F23: HAND CREAM | G23: 5 | H23: ACRYLATES COPOLYMER | I23: 25035-69-2;25212-88-8;25685-29-4;159666-35-0 | J23: 1.2 | K23: SAH155
A24: 23 | B24: SAH155 & SAH157 INGREDIENTS for Cat Pop Hand Cream.xlsx | C24: HAND CREAM | D24: SAH155 | E24: SAH155 - PEACH | F24: HAND CREAM | G24: 6 | H24: DIMETHICONE | I24: 63148-62-9 | J24: 0.5 | K24: SAH155
A25: 24 | B25: SAH155 & SAH157 INGREDIENTS for Cat Pop Hand Cream.xlsx | C25: HAND CREAM | D25: SAH155 | E25: SAH155 - PEACH | F25: HAND CREAM | G25: 7 | H25: DIAZOLIDINYL UREA | I25: 78491-02-8 | J25: 0.2 | K25: SAH155
A26: 25 | B26: SAH155 & SAH157 INGREDIENTS for Cat Pop Hand Cream.xlsx | C26: HAND CREAM | D26: SAH155 | E26: SAH155 - PEACH | F26: HAND CREAM | G26: 8 | H26: METHYLPARABEN | I26: 99-76-3 | J26: 0.2 | K26: SAH155
A27: 26 | B27: SAH155 & SAH157 INGREDIENTS for Cat Pop Hand Cream.xlsx | C27: HAND CREAM | D27: SAH155 | E27: SAH155 - PEACH | F27: HAND CREAM | G27: 9 | H27: FRAGRANCE | J27: 0.2 | K27: SAH155
A28: 27 | B28: SAH155 & SAH157 INGREDIENTS for Cat Pop Hand Cream.xlsx | C28: HAND CREAM | D28: SAH155 | E28: SAH155 - PEACH | F28: HAND CREAM | G28: 10 | H28: PROPYLPARABEN | I28: 94-13-3 | J28: 0.1 | K28: SAH155
A29: 28 | B29: SAH155 & SAH157 INGREDIENTS for Cat Pop Hand Cream.xlsx | C29: HAND CREAM | D29: SAH155 | E29: SAH155 - PEACH | F29: HAND CREAM | G29: 11 | H29: XANTHAN GUM | I29: 11138-66-2 | J29: 0.05 | K29: SAH155
A30: 29 | B30: SAH155 & SAH157 INGREDIENTS for Cat Pop Hand Cream.xlsx | C30: HAND CREAM | D30: SAH155 | E30: SAH155 - PEACH | F30: HAND CREAM | G30: 12 | H30: PRUNUS PERSICA (PEACH) FRUIT EXTRACT | I30: 84012-34-0 | J30: 0.01 | K30: SAH155
A31: 30 | B31: SAH155 & SAH157 INGREDIENTS for Cat Pop Hand Cream.xlsx | C31: HAND CREAM | D31: SAH157 | E31: SAH157 - VITAMIN C | F31: HAND CREAM | G31: 1 | H31: WATER | I31: 7732-18-5 | J31: 91.3 | K31: SAH157
A32: 31 | B32: SAH155 & SAH157 INGREDIENTS for Cat Pop Hand Cream.xlsx | C32: HAND CREAM | D32: SAH157 | E32: SAH157 - VITAMIN C | F32: HAND CREAM | G32: 2 | H32: MINERAL OIL | I32: 8012-95-1;8020-83-5;8042-47-5 | J32: 3 | K32: SAH157
A33: 32 | B33: SAH155 & SAH157 INGREDIENTS for Cat Pop Hand Cream.xlsx | C33: HAND CREAM | D33: SAH157 | E33: SAH157 - VITAMIN C | F33: HAND CREAM | G33: 3 | H33: PETROLATUM | I33: 8009-03-8 | J33: 2 | K33: SAH157
A34: 33 | B34: SAH155 & SAH157 INGREDIENTS for Cat Pop Hand Cream.xlsx | C34: HAND CREAM | D34: SAH157 | E34: SAH157 - VITAMIN C | F34: HAND CREAM | G34: 4 | H34: CETEARYL ALCOHOL | I34: 8005-44-5;67762-27-0 | J34: 1.2 | K34: SAH157
A35: 34 | B35: SAH155 & SAH157 INGREDIENTS for Cat Pop Hand Cream.xlsx | C35: HAND CREAM | D35: SAH157 | E35: SAH157 - VITAMIN C | F35: HAND CREAM | G35: 5 | H35: ACRYLATES COPOLYMER | I35: 25035-69-2;25212-88-8;25685-29-4;159666-35-0 | J35: 1.2 | K35: SAH157
A36: 35 | B36: SAH155 & SAH157 INGREDIENTS for Cat Pop Hand Cream.xlsx | C36: HAND CREAM | D36: SAH157 | E36: SAH157 - VITAMIN C | F36: HAND CREAM | G36: 6 | H36: DIMETHICONE | I36: 63148-62-9 | J36: 0.5 | K36: SAH157
A37: 36 | B37: SAH155 & SAH157 INGREDIENTS for Cat Pop Hand Cream.xlsx | C37: HAND CREAM | D37: SAH157 | E37: SAH157 - VITAMIN C | F37: HAND CREAM | G37: 7 | H37: DIAZOLIDINYL UREA | I37: 78491-02-8 | J37: 0.2 | K37: SAH157
A38: 37 | B38: SAH155 & SAH157 INGREDIENTS for Cat Pop Hand Cream.xlsx | C38: HAND CREAM | D38: SAH157 | E38: SAH157 - VITAMIN C | F38: HAND CREAM | G38: 8 | H38: METHYLPARABEN | I38: 99-76-3 | J38: 0.2 | K38: SAH157
A39: 38 | B39: SAH155 & SAH157 INGREDIENTS for Cat Pop Hand Cream.xlsx | C39: HAND CREAM | D39: SAH157 | E39: SAH157 - VITAMIN C | F39: HAND CREAM | G39: 9 | H39: FRAGRANCE | J39: 0.2 | K39: SAH157
A40: 39 | B40: SAH155 & SAH157 INGREDIENTS for Cat Pop Hand Cream.xlsx | C40: HAND CREAM | D40: SAH157 | E40: SAH157 - VITAMIN C | F40: HAND CREAM | G40: 10 | H40: PROPYLPARABEN | I40: 94-13-3 | J40: 0.1 | K40: SAH157
...

Sheet 03_筛查输出模板
A1: Client Input | I1: Matching / Normalization | N1: CA Prohibited | S1: CA Restricted | Z1: CIR | AE1: CFR | AH1: Overall Review
A2: Record ID | B2: Formula Code | C2: Formula Name | D2: Ingredient No | E2: Raw INCI Name | F2: Raw CAS No | G2: Input W/W % | H2: Product Family | I2: Normalized / Screening Key Name | J2: Normalized / Screening Key CAS | K2: Match Method | L2: Match Confidence | M2: Manual Review? | N2: CA Prohibited Hit | O2: CA Prohibited Matched Ingredient | P2: CA Prohibited CAS | Q2: CA Prohibited Synonyms / Related | R2: CA Prohibited Evidence | S2: CA Restricted Hit | T2: CA Restricted Matched Ingredient | U2: CA Restricted CAS | V2: Conditions of Use / Allowed Body Site | W2: Max Conc. Permitted | X2: Warning Statement | Y2: Restriction Assessment Note | Z2: CIR Hit | AA2: CIR Matched Ingredient | AB2: Finding | AC2: Conclusion | AD2: CIR Interpretation | AE2: CFR Hit | AF2: CFR Matched Substance | AG2: CFR Evidence | AH2: Hard Stop? | AI2: Regulatory Summary | AJ2: Recommended Action | AK2: Final Disposition | AL2: Reviewer / AI Notes | AM2: Checked By | AN2: Checked Date
A3: 1 | B3: HA440 | C3: FACIAL MASK - CAKE | D3: 1 | E3: WATER | F3: 7732-18-5 | G3: 90.605 | H3: FACIAL MASK - CAKE | I3: =E3 | J3: =F3 | AH3: =IF(OR(N3="Y",AE3="Y"),"Y","N") | AI3: =IF(AH3="Y","Prohibited hit in CA/CFR",IF(S3="Y","Restricted - assess body site / max conc. / warning",IF(Z3="Y","No prohibition/restriction hit; CIR reference found","No hit in loaded 4 databases"))) | AJ3: =IF(AH3="Y","Reformulate / reject / escalate",IF(S3="Y","Manual compliance assessment required","Keep as reference / no restriction found in current databases"))
A4: 2 | B4: HA440 | C4: FACIAL MASK - CAKE | D4: 2 | E4: PROPYLENE GLYCOL | F4: 57-55-6 | G4: 4.348 | H4: FACIAL MASK - CAKE | I4: =E4 | J4: =F4 | AH4: =IF(OR(N4="Y",AE4="Y"),"Y","N") | AI4: =IF(AH4="Y","Prohibited hit in CA/CFR",IF(S4="Y","Restricted - assess body site / max conc. / warning",IF(Z4="Y","No prohibition/restriction hit; CIR reference found","No hit in loaded 4 databases"))) | AJ4: =IF(AH4="Y","Reformulate / reject / escalate",IF(S4="Y","Manual compliance assessment required","Keep as reference / no restriction found in current databases"))
A5: 3 | B5: HA440 | C5: FACIAL MASK - CAKE | D5: 3 | E5: GLYCERIN | F5: 56-81-5 | G5: 4 | H5: FACIAL MASK - CAKE | I5: =E5 | J5: =F5 | AH5: =IF(OR(N5="Y",AE5="Y"),"Y","N") | AI5: =IF(AH5="Y","Prohibited hit in CA/CFR",IF(S5="Y","Restricted - assess body site / max conc. / warning",IF(Z5="Y","No prohibition/restriction hit; CIR reference found","No hit in loaded 4 databases"))) | AJ5: =IF(AH5="Y","Reformulate / reject / escalate",IF(S5="Y","Manual compliance assessment required","Keep as reference / no restriction found in current databases"))
A6: 4 | B6: HA440 | C6: FACIAL MASK - CAKE | D6: 4 | E6: HYDROXYACETOPHENONE | F6: 99-93-4 | G6: 0.4 | H6: FACIAL MASK - CAKE | I6: =E6 | J6: =F6 | AH6: =IF(OR(N6="Y",AE6="Y"),"Y","N") | AI6: =IF(AH6="Y","Prohibited hit in CA/CFR",IF(S6="Y","Restricted - assess body site / max conc. / warning",IF(Z6="Y","No prohibition/restriction hit; CIR reference found","No hit in loaded 4 databases"))) | AJ6: =IF(AH6="Y","Reformulate / reject / escalate",IF(S6="Y","Manual compliance assessment required","Keep as reference / no restriction found in current databases"))
A7: 5 | B7: HA440 | C7: FACIAL MASK - CAKE | D7: 5 | E7: ALLANTOIN | F7: 97-59-6 | G7: 0.2 | H7: FACIAL MASK - CAKE | I7: =E7 | J7: =F7 | AH7: =IF(OR(N7="Y",AE7="Y"),"Y","N") | AI7: =IF(AH7="Y","Prohibited hit in CA/CFR",IF(S7="Y","Restricted - assess body site / max conc. / warning",IF(Z7="Y","No prohibition/restriction hit; CIR reference found","No hit in loaded 4 databases"))) | AJ7: =IF(AH7="Y","Reformulate / reject / escalate",IF(S7="Y","Manual compliance assessment required","Keep as reference / no restriction found in current databases"))
A8: 6 | B8: HA440 | C8: FACIAL MASK - CAKE | D8: 6 | E8: HYDROXYETHYLCELLULOSE | F8: 9004-62-0 | G8: 0.1978 | H8: FACIAL MASK - CAKE | I8: =E8 | J8: =F8 | AH8: =IF(OR(N8="Y",AE8="Y"),"Y","N") | AI8: =IF(AH8="Y","Prohibited hit in CA/CFR",IF(S8="Y","Restricted - assess body site / max conc. / warning",IF(Z8="Y","No prohibition/restriction hit; CIR reference found","No hit in loaded 4 databases"))) | AJ8: =IF(AH8="Y","Reformulate / reject / escalate",IF(S8="Y","Manual compliance assessment required","Keep as reference / no restriction found in current databases"))
A9: 7 | B9: HA440 | C9: FACIAL MASK - CAKE | D9: 7 | E9: CARBOMER | F9: 9007-20-9 | G9: 0.08 | H9: FACIAL MASK - CAKE | I9: =E9 | J9: =F9 | AH9: =IF(OR(N9="Y",AE9="Y"),"Y","N") | AI9: =IF(AH9="Y","Prohibited hit in CA/CFR",IF(S9="Y","Restricted - assess body site / max conc. / warning",IF(Z9="Y","No prohibition/restriction hit; CIR reference found","No hit in loaded 4 databases"))) | AJ9: =IF(AH9="Y","Reformulate / reject / escalate",IF(S9="Y","Manual compliance assessment required","Keep as reference / no restriction found in current databases"))
A10: 8 | B10: HA440 | C10: FACIAL MASK - CAKE | D10: 8 | E10: TRIETHANOLAMINE | F10: 102-71-6 | G10: 0.08 | H10: FACIAL MASK - CAKE | I10: =E10 | J10: =F10 | AH10: =IF(OR(N10="Y",AE10="Y"),"Y","N") | AI10: =IF(AH10="Y","Prohibited hit in CA/CFR",IF(S10="Y","Restricted - assess body site / max conc. / warning",IF(Z10="Y","No prohibition/restriction hit; CIR reference found","No hit in loaded 4 databases"))) | AJ10: =IF(AH10="Y","Reformulate / reject / escalate",IF(S10="Y","Manual compliance assessment required","Keep as reference / no restriction found in current databases"))
A11: 9 | B11: HA440 | C11: FACIAL MASK - CAKE | D11: 9 | E11: CAPRYLHYDROXAMIC ACID | G11: 0.048 | H11: FACIAL MASK - CAKE | I11: =E11 | J11: =F11 | AH11: =IF(OR(N11="Y",AE11="Y"),"Y","N") | AI11: =IF(AH11="Y","Prohibited hit in CA/CFR",IF(S11="Y","Restricted - assess body site / max conc. / warning",IF(Z11="Y","No prohibition/restriction hit; CIR reference found","No hit in loaded 4 databases"))) | AJ11: =IF(AH11="Y","Reformulate / reject / escalate",IF(S11="Y","Manual compliance assessment required","Keep as reference / no restriction found in current databases"))
A12: 10 | B12: HA440 | C12: FACIAL MASK - CAKE | D12: 10 | E12: DISODIUM EDTA | F12: 139-33-3 | G12: 0.03 | H12: FACIAL MASK - CAKE | I12: =E12 | J12: =F12 | AH12: =IF(OR(N12="Y",AE12="Y"),"Y","N") | AI12: =IF(AH12="Y","Prohibited hit in CA/CFR",IF(S12="Y","Restricted - assess body site / max conc. / warning",IF(Z12="Y","No prohibition/restriction hit; CIR reference found","No hit in loaded 4 databases"))) | AJ12: =IF(AH12="Y","Reformulate / reject / escalate",IF(S12="Y","Manual compliance assessment required","Keep as reference / no restriction found in current databases"))
A13: 11 | B13: HA440 | C13: FACIAL MASK - CAKE | D13: 11 | E13: GLYCERYL CAPRYLATE | F13: 26402-26-6 | G13: 0.004 | H13: FACIAL MASK - CAKE | I13: =E13 | J13: =F13 | AH13: =IF(OR(N13="Y",AE13="Y"),"Y","N") | AI13: =IF(AH13="Y","Prohibited hit in CA/CFR",IF(S13="Y","Restricted - assess body site / max conc. / warning",IF(Z13="Y","No prohibition/restriction hit; CIR reference found","No hit in loaded 4 databases"))) | AJ13: =IF(AH13="Y","Reformulate / reject / escalate",IF(S13="Y","Manual compliance assessment required","Keep as reference / no restriction found in current databases"))
A14: 12 | B14: HA440 | C14: FACIAL MASK - CAKE | D14: 12 | E14: PEG-40 HYDROGENATED CASTOR OIL | F14: 61788-85-0 | G14: 0.0036 | H14: FACIAL MASK - CAKE | I14: =E14 | J14: =F14 | AH14: =IF(OR(N14="Y",AE14="Y"),"Y","N") | AI14: =IF(AH14="Y","Prohibited hit in CA/CFR",IF(S14="Y","Restricted - assess body site / max conc. / warning",IF(Z14="Y","No prohibition/restriction hit; CIR reference found","No hit in loaded 4 databases"))) | AJ14: =IF(AH14="Y","Reformulate / reject / escalate",IF(S14="Y","Manual compliance assessment required","Keep as reference / no restriction found in current databases"))
A15: 13 | B15: HA440 | C15: FACIAL MASK - CAKE | D15: 13 | E15: FRAGRANCE | G15: 0.001 | H15: FACIAL MASK - CAKE | I15: =E15 | J15: =F15 | AH15: =IF(OR(N15="Y",AE15="Y"),"Y","N") | AI15: =IF(AH15="Y","Prohibited hit in CA/CFR",IF(S15="Y","Restricted - assess body site / max conc. / warning",IF(Z15="Y","No prohibition/restriction hit; CIR reference found","No hit in loaded 4 databases"))) | AJ15: =IF(AH15="Y","Reformulate / reject / escalate",IF(S15="Y","Manual compliance assessment required","Keep as reference / no restriction found in current databases"))
A16: 14 | B16: HA440 | C16: FACIAL MASK - CAKE | D16: 14 | E16: POLYSORBATE 60 | F16: 9005-67-8 | G16: 0.001 | H16: FACIAL MASK - CAKE | I16: =E16 | J16: =F16 | AH16: =IF(OR(N16="Y",AE16="Y"),"Y","N") | AI16: =IF(AH16="Y","Prohibited hit in CA/CFR",IF(S16="Y","Restricted - assess body site / max conc. / warning",IF(Z16="Y","No prohibition/restriction hit; CIR reference found","No hit in loaded 4 databases"))) | AJ16: =IF(AH16="Y","Reformulate / reject / escalate",IF(S16="Y","Manual compliance assessment required","Keep as reference / no restriction found in current databases"))
A17: 15 | B17: HA440 | C17: FACIAL MASK - CAKE | D17: 15 | E17: DISODIUM PHOSPHATE | F17: 7558-79-4 | G17: 0.001 | H17: FACIAL MASK - CAKE | I17: =E17 | J17: =F17 | AH17: =IF(OR(N17="Y",AE17="Y"),"Y","N") | AI17: =IF(AH17="Y","Prohibited hit in CA/CFR",IF(S17="Y","Restricted - assess body site / max conc. / warning",IF(Z17="Y","No prohibition/restriction hit; CIR reference found","No hit in loaded 4 databases"))) | AJ17: =IF(AH17="Y","Reformulate / reject / escalate",IF(S17="Y","Manual compliance assessment required","Keep as reference / no restriction found in current databases"))
A18: 16 | B18: HA440 | C18: FACIAL MASK - CAKE | D18: 16 | E18: PEG-10 | F18: 5579-66-8/25322-68-3 | G18: 0.0004 | H18: FACIAL MASK - CAKE | I18: =E18 | J18: =F18 | AH18: =IF(OR(N18="Y",AE18="Y"),"Y","N") | AI18: =IF(AH18="Y","Prohibited hit in CA/CFR",IF(S18="Y","Restricted - assess body site / max conc. / warning",IF(Z18="Y","No prohibition/restriction hit; CIR reference found","No hit in loaded 4 databases"))) | AJ18: =IF(AH18="Y","Reformulate / reject / escalate",IF(S18="Y","Manual compliance assessment required","Keep as reference / no restriction found in current databases"))
A19: 17 | B19: HA440 | C19: FACIAL MASK - CAKE | D19: 17 | E19: SODIUM PHOSPHATE | F19: 7558-80-7 | G19: 0.0002 | H19: FACIAL MASK - CAKE | I19: =E19 | J19: =F19 | AH19: =IF(OR(N19="Y",AE19="Y"),"Y","N") | AI19: =IF(AH19="Y","Prohibited hit in CA/CFR",IF(S19="Y","Restricted - assess body site / max conc. / warning",IF(Z19="Y","No prohibition/restriction hit; CIR reference found","No hit in loaded 4 databases"))) | AJ19: =IF(AH19="Y","Reformulate / reject / escalate",IF(S19="Y","Manual compliance assessment required","Keep as reference / no restriction found in current databases"))
A20: 18 | B20: SAH155 | C20: SAH155 - PEACH | D20: 1 | E20: WATER | F20: 7732-18-5 | G20: 91.34 | H20: HAND CREAM | I20: =E20 | J20: =F20 | AH20: =IF(OR(N20="Y",AE20="Y"),"Y","N") | AI20: =IF(AH20="Y","Prohibited hit in CA/CFR",IF(S20="Y","Restricted - assess body site / max conc. / warning",IF(Z20="Y","No prohibition/restriction hit; CIR reference found","No hit in loaded 4 databases"))) | AJ20: =IF(AH20="Y","Reformulate / reject / escalate",IF(S20="Y","Manual compliance assessment required","Keep as reference / no restriction found in current databases"))
A21: 19 | B21: SAH155 | C21: SAH155 - PEACH | D21: 2 | E21: MINERAL OIL | F21: 8012-95-1;8020-83-5;8042-47-5 | G21: 3 | H21: HAND CREAM | I21: =E21 | J21: =F21 | AH21: =IF(OR(N21="Y",AE21="Y"),"Y","N") | AI21: =IF(AH21="Y","Prohibited hit in CA/CFR",IF(S21="Y","Restricted - assess body site / max conc. / warning",IF(Z21="Y","No prohibition/restriction hit; CIR reference found","No hit in loaded 4 databases"))) | AJ21: =IF(AH21="Y","Reformulate / reject / escalate",IF(S21="Y","Manual compliance assessment required","Keep as reference / no restriction found in current databases"))
A22: 20 | B22: SAH155 | C22: SAH155 - PEACH | D22: 3 | E22: PETROLATUM | F22: 8009-03-8 | G22: 2 | H22: HAND CREAM | I22: =E22 | J22: =F22 | AH22: =IF(OR(N22="Y",AE22="Y"),"Y","N") | AI22: =IF(AH22="Y","Prohibited hit in CA/CFR",IF(S22="Y","Restricted - assess body site / max conc. / warning",IF(Z22="Y","No prohibition/restriction hit; CIR reference found","No hit in loaded 4 databases"))) | AJ22: =IF(AH22="Y","Reformulate / reject / escalate",IF(S22="Y","Manual compliance assessment required","Keep as reference / no restriction found in current databases"))
A23: 21 | B23: SAH155 | C23: SAH155 - PEACH | D23: 4 | E23: CETEARYL ALCOHOL | F23: 8005-44-5;67762-27-0 | G23: 1.2 | H23: HAND CREAM | I23: =E23 | J23: =F23 | AH23: =IF(OR(N23="Y",AE23="Y"),"Y","N") | AI23: =IF(AH23="Y","Prohibited hit in CA/CFR",IF(S23="Y","Restricted - assess body site / max conc. / warning",IF(Z23="Y","No prohibition/restriction hit; CIR reference found","No hit in loaded 4 databases"))) | AJ23: =IF(AH23="Y","Reformulate / reject / escalate",IF(S23="Y","Manual compliance assessment required","Keep as reference / no restriction found in current databases"))
A24: 22 | B24: SAH155 | C24: SAH155 - PEACH | D24: 5 | E24: ACRYLATES COPOLYMER | F24: 25035-69-2;25212-88-8;25685-29-4;159666-35-0 | G24: 1.2 | H24: HAND CREAM | I24: =E24 | J24: =F24 | AH24: =IF(OR(N24="Y",AE24="Y"),"Y","N") | AI24: =IF(AH24="Y","Prohibited hit in CA/CFR",IF(S24="Y","Restricted - assess body site / max conc. / warning",IF(Z24="Y","No prohibition/restriction hit; CIR reference found","No hit in loaded 4 databases"))) | AJ24: =IF(AH24="Y","Reformulate / reject / escalate",IF(S24="Y","Manual compliance assessment required","Keep as reference / no restriction found in current databases"))
A25: 23 | B25: SAH155 | C25: SAH155 - PEACH | D25: 6 | E25: DIMETHICONE | F25: 63148-62-9 | G25: 0.5 | H25: HAND CREAM | I25: =E25 | J25: =F25 | AH25: =IF(OR(N25="Y",AE25="Y"),"Y","N") | AI25: =IF(AH25="Y","Prohibited hit in CA/CFR",IF(S25="Y","Restricted - assess body site / max conc. / warning",IF(Z25="Y","No prohibition/restriction hit; CIR reference found","No hit in loaded 4 databases"))) | AJ25: =IF(AH25="Y","Reformulate / reject / escalate",IF(S25="Y","Manual compliance assessment required","Keep as reference / no restriction found in current databases"))
A26: 24 | B26: SAH155 | C26: SAH155 - PEACH | D26: 7 | E26: DIAZOLIDINYL UREA | F26: 78491-02-8 | G26: 0.2 | H26: HAND CREAM | I26: =E26 | J26: =F26 | AH26: =IF(OR(N26="Y",AE26="Y"),"Y","N") | AI26: =IF(AH26="Y","Prohibited hit in CA/CFR",IF(S26="Y","Restricted - assess body site / max conc. / warning",IF(Z26="Y","No prohibition/restriction hit; CIR reference found","No hit in loaded 4 databases"))) | AJ26: =IF(AH26="Y","Reformulate / reject / escalate",IF(S26="Y","Manual compliance assessment required","Keep as reference / no restriction found in current databases"))
A27: 25 | B27: SAH155 | C27: SAH155 - PEACH | D27: 8 | E27: METHYLPARABEN | F27: 99-76-3 | G27: 0.2 | H27: HAND CREAM | I27: =E27 | J27: =F27 | AH27: =IF(OR(N27="Y",AE27="Y"),"Y","N") | AI27: =IF(AH27="Y","Prohibited hit in CA/CFR",IF(S27="Y","Restricted - assess body site / max conc. / warning",IF(Z27="Y","No prohibition/restriction hit; CIR reference found","No hit in loaded 4 databases"))) | AJ27: =IF(AH27="Y","Reformulate / reject / escalate",IF(S27="Y","Manual compliance assessment required","Keep as reference / no restriction found in current databases"))
A28: 26 | B28: SAH155 | C28: SAH155 - PEACH | D28: 9 | E28: FRAGRANCE | G28: 0.2 | H28: HAND CREAM | I28: =E28 | J28: =F28 | AH28: =IF(OR(N28="Y",AE28="Y"),"Y","N") | AI28: =IF(AH28="Y","Prohibited hit in CA/CFR",IF(S28="Y","Restricted - assess body site / max conc. / warning",IF(Z28="Y","No prohibition/restriction hit; CIR reference found","No hit in loaded 4 databases"))) | AJ28: =IF(AH28="Y","Reformulate / reject / escalate",IF(S28="Y","Manual compliance assessment required","Keep as reference / no restriction found in current databases"))
A29: 27 | B29: SAH155 | C29: SAH155 - PEACH | D29: 10 | E29: PROPYLPARABEN | F29: 94-13-3 | G29: 0.1 | H29: HAND CREAM | I29: =E29 | J29: =F29 | AH29: =IF(OR(N29="Y",AE29="Y"),"Y","N") | AI29: =IF(AH29="Y","Prohibited hit in CA/CFR",IF(S29="Y","Restricted - assess body site / max conc. / warning",IF(Z29="Y","No prohibition/restriction hit; CIR reference found","No hit in loaded 4 databases"))) | AJ29: =IF(AH29="Y","Reformulate / reject / escalate",IF(S29="Y","Manual compliance assessment required","Keep as reference / no restriction found in current databases"))
A30: 28 | B30: SAH155 | C30: SAH155 - PEACH | D30: 11 | E30: XANTHAN GUM | F30: 11138-66-2 | G30: 0.05 | H30: HAND CREAM | I30: =E30 | J30: =F30 | AH30: =IF(OR(N30="Y",AE30="Y"),"Y","N") | AI30: =IF(AH30="Y","Prohibited hit in CA/CFR",IF(S30="Y","Restricted - assess body site / max conc. / warning",IF(Z30="Y","No prohibition/restriction hit; CIR reference found","No hit in loaded 4 databases"))) | AJ30: =IF(AH30="Y","Reformulate / reject / escalate",IF(S30="Y","Manual compliance assessment required","Keep as reference / no restriction found in current databases"))
A31: 29 | B31: SAH155 | C31: SAH155 - PEACH | D31: 12 | E31: PRUNUS PERSICA (PEACH) FRUIT EXTRACT | F31: 84012-34-0 | G31: 0.01 | H31: HAND CREAM | I31: =E31 | J31: =F31 | AH31: =IF(OR(N31="Y",AE31="Y"),"Y","N") | AI31: =IF(AH31="Y","Prohibited hit in CA/CFR",IF(S31="Y","Restricted - assess body site / max conc. / warning",IF(Z31="Y","No prohibition/restriction hit; CIR reference found","No hit in loaded 4 databases"))) | AJ31: =IF(AH31="Y","Reformulate / reject / escalate",IF(S31="Y","Manual compliance assessment required","Keep as reference / no restriction found in current databases"))
A32: 30 | B32: SAH157 | C32: SAH157 - VITAMIN C | D32: 1 | E32: WATER | F32: 7732-18-5 | G32: 91.3 | H32: HAND CREAM | I32: =E32 | J32: =F32 | AH32: =IF(OR(N32="Y",AE32="Y"),"Y","N") | AI32: =IF(AH32="Y","Prohibited hit in CA/CFR",IF(S32="Y","Restricted - assess body site / max conc. / warning",IF(Z32="Y","No prohibition/restriction hit; CIR reference found","No hit in loaded 4 databases"))) | AJ32: =IF(AH32="Y","Reformulate / reject / escalate",IF(S32="Y","Manual compliance assessment required","Keep as reference / no restriction found in current databases"))
A33: 31 | B33: SAH157 | C33: SAH157 - VITAMIN C | D33: 2 | E33: MINERAL OIL | F33: 8012-95-1;8020-83-5;8042-47-5 | G33: 3 | H33: HAND CREAM | I33: =E33 | J33: =F33 | AH33: =IF(OR(N33="Y",AE33="Y"),"Y","N") | AI33: =IF(AH33="Y","Prohibited hit in CA/CFR",IF(S33="Y","Restricted - assess body site / max conc. / warning",IF(Z33="Y","No prohibition/restriction hit; CIR reference found","No hit in loaded 4 databases"))) | AJ33: =IF(AH33="Y","Reformulate / reject / escalate",IF(S33="Y","Manual compliance assessment required","Keep as reference / no restriction found in current databases"))
A34: 32 | B34: SAH157 | C34: SAH157 - VITAMIN C | D34: 3 | E34: PETROLATUM | F34: 8009-03-8 | G34: 2 | H34: HAND CREAM | I34: =E34 | J34: =F34 | AH34: =IF(OR(N34="Y",AE34="Y"),"Y","N") | AI34: =IF(AH34="Y","Prohibited hit in CA/CFR",IF(S34="Y","Restricted - assess body site / max conc. / warning",IF(Z34="Y","No prohibition/restriction hit; CIR reference found","No hit in loaded 4 databases"))) | AJ34: =IF(AH34="Y","Reformulate / reject / escalate",IF(S34="Y","Manual compliance assessment required","Keep as reference / no restriction found in current databases"))
A35: 33 | B35: SAH157 | C35: SAH157 - VITAMIN C | D35: 4 | E35: CETEARYL ALCOHOL | F35: 8005-44-5;67762-27-0 | G35: 1.2 | H35: HAND CREAM | I35: =E35 | J35: =F35 | AH35: =IF(OR(N35="Y",AE35="Y"),"Y","N") | AI35: =IF(AH35="Y","Prohibited hit in CA/CFR",IF(S35="Y","Restricted - assess body site / max conc. / warning",IF(Z35="Y","No prohibition/restriction hit; CIR reference found","No hit in loaded 4 databases"))) | AJ35: =IF(AH35="Y","Reformulate / reject / escalate",IF(S35="Y","Manual compliance assessment required","Keep as reference / no restriction found in current databases"))
A36: 34 | B36: SAH157 | C36: SAH157 - VITAMIN C | D36: 5 | E36: ACRYLATES COPOLYMER | F36: 25035-69-2;25212-88-8;25685-29-4;159666-35-0 | G36: 1.2 | H36: HAND CREAM | I36: =E36 | J36: =F36 | AH36: =IF(OR(N36="Y",AE36="Y"),"Y","N") | AI36: =IF(AH36="Y","Prohibited hit in CA/CFR",IF(S36="Y","Restricted - assess body site / max conc. / warning",IF(Z36="Y","No prohibition/restriction hit; CIR reference found","No hit in loaded 4 databases"))) | AJ36: =IF(AH36="Y","Reformulate / reject / escalate",IF(S36="Y","Manual compliance assessment required","Keep as reference / no restriction found in current databases"))
A37: 35 | B37: SAH157 | C37: SAH157 - VITAMIN C | D37: 6 | E37: DIMETHICONE | F37: 63148-62-9 | G37: 0.5 | H37: HAND CREAM | I37: =E37 | J37: =F37 | AH37: =IF(OR(N37="Y",AE37="Y"),"Y","N") | AI37: =IF(AH37="Y","Prohibited hit in CA/CFR",IF(S37="Y","Restricted - assess body site / max conc. / warning",IF(Z37="Y","No prohibition/restriction hit; CIR reference found","No hit in loaded 4 databases"))) | AJ37: =IF(AH37="Y","Reformulate / reject / escalate",IF(S37="Y","Manual compliance assessment required","Keep as reference / no restriction found in current databases"))
A38: 36 | B38: SAH157 | C38: SAH157 - VITAMIN C | D38: 7 | E38: DIAZOLIDINYL UREA | F38: 78491-02-8 | G38: 0.2 | H38: HAND CREAM | I38: =E38 | J38: =F38 | AH38: =IF(OR(N38="Y",AE38="Y"),"Y","N") | AI38: =IF(AH38="Y","Prohibited hit in CA/CFR",IF(S38="Y","Restricted - assess body site / max conc. / warning",IF(Z38="Y","No prohibition/restriction hit; CIR reference found","No hit in loaded 4 databases"))) | AJ38: =IF(AH38="Y","Reformulate / reject / escalate",IF(S38="Y","Manual compliance assessment required","Keep as reference / no restriction found in current databases"))
A39: 37 | B39: SAH157 | C39: SAH157 - VITAMIN C | D39: 8 | E39: METHYLPARABEN | F39: 99-76-3 | G39: 0.2 | H39: HAND CREAM | I39: =E39 | J39: =F39 | AH39: =IF(OR(N39="Y",AE39="Y"),"Y","N") | AI39: =IF(AH39="Y","Prohibited hit in CA/CFR",IF(S39="Y","Restricted - assess body site / max conc. / warning",IF(Z39="Y","No prohibition/restriction hit; CIR reference found","No hit in loaded 4 databases"))) | AJ39: =IF(AH39="Y","Reformulate / reject / escalate",IF(S39="Y","Manual compliance assessment required","Keep as reference / no restriction found in current databases"))
A40: 38 | B40: SAH157 | C40: SAH157 - VITAMIN C | D40: 9 | E40: FRAGRANCE | G40: 0.2 | H40: HAND CREAM | I40: =E40 | J40: =F40 | AH40: =IF(OR(N40="Y",AE40="Y"),"Y","N") | AI40: =IF(AH40="Y","Prohibited hit in CA/CFR",IF(S40="Y","Restricted - assess body site / max conc. / warning",IF(Z40="Y","No prohibition/restriction hit; CIR reference found","No hit in loaded 4 databases"))) | AJ40: =IF(AH40="Y","Reformulate / reject / escalate",IF(S40="Y","Manual compliance assessment required","Keep as reference / no restriction found in current databases"))
...

Sheet 04_配方汇总
A1: Formula Code | B1: Formula Name | C1: Product Family | D1: Ingredient Count | E1: CA Prohibited Hits | F1: CA Restricted Hits | G1: CIR References | H1: CFR Hits | I1: Manual Review Count | J1: Overall Formula Status | K1: Follow-up
A2: HA440 | B2: FACIAL MASK - CAKE | C2: FACIAL MASK - CAKE | D2: =COUNTIF('03_筛查输出模板'!$B:$B,A2) | E2: =COUNTIFS('03_筛查输出模板'!$B:$B,A2,'03_筛查输出模板'!$N:$N,"Y") | F2: =COUNTIFS('03_筛查输出模板'!$B:$B,A2,'03_筛查输出模板'!$S:$S,"Y") | G2: =COUNTIFS('03_筛查输出模板'!$B:$B,A2,'03_筛查输出模板'!$Z:$Z,"Y") | H2: =COUNTIFS('03_筛查输出模板'!$B:$B,A2,'03_筛查输出模板'!$AE:$AE,"Y") | I2: =COUNTIFS('03_筛查输出模板'!$B:$B,A2,'03_筛查输出模板'!$M:$M,"Y")+COUNTIFS('03_筛查输出模板'!$B:$B,A2,'03_筛查输出模板'!$M:$M,"MAYBE") | J2: =IF(OR(E2>0,H2>0),"Prohibited hit present",IF(F2>0,"Restricted review needed",IF(I2>0,"Manual review needed","No flagged hits yet"))) | K2: =IF(OR(E2>0,H2>0),"Escalate immediately",IF(F2>0,"Check body site / max conc. / warnings",IF(I2>0,"Resolve fuzzy match / naming","Proceed with routine review")))
A3: SAH155 | B3: SAH155 - PEACH | C3: HAND CREAM | D3: =COUNTIF('03_筛查输出模板'!$B:$B,A3) | E3: =COUNTIFS('03_筛查输出模板'!$B:$B,A3,'03_筛查输出模板'!$N:$N,"Y") | F3: =COUNTIFS('03_筛查输出模板'!$B:$B,A3,'03_筛查输出模板'!$S:$S,"Y") | G3: =COUNTIFS('03_筛查输出模板'!$B:$B,A3,'03_筛查输出模板'!$Z:$Z,"Y") | H3: =COUNTIFS('03_筛查输出模板'!$B:$B,A3,'03_筛查输出模板'!$AE:$AE,"Y") | I3: =COUNTIFS('03_筛查输出模板'!$B:$B,A3,'03_筛查输出模板'!$M:$M,"Y")+COUNTIFS('03_筛查输出模板'!$B:$B,A3,'03_筛查输出模板'!$M:$M,"MAYBE") | J3: =IF(OR(E3>0,H3>0),"Prohibited hit present",IF(F3>0,"Restricted review needed",IF(I3>0,"Manual review needed","No flagged hits yet"))) | K3: =IF(OR(E3>0,H3>0),"Escalate immediately",IF(F3>0,"Check body site / max conc. / warnings",IF(I3>0,"Resolve fuzzy match / naming","Proceed with routine review")))
A4: SAH157 | B4: SAH157 - VITAMIN C | C4: HAND CREAM | D4: =COUNTIF('03_筛查输出模板'!$B:$B,A4) | E4: =COUNTIFS('03_筛查输出模板'!$B:$B,A4,'03_筛查输出模板'!$N:$N,"Y") | F4: =COUNTIFS('03_筛查输出模板'!$B:$B,A4,'03_筛查输出模板'!$S:$S,"Y") | G4: =COUNTIFS('03_筛查输出模板'!$B:$B,A4,'03_筛查输出模板'!$Z:$Z,"Y") | H4: =COUNTIFS('03_筛查输出模板'!$B:$B,A4,'03_筛查输出模板'!$AE:$AE,"Y") | I4: =COUNTIFS('03_筛查输出模板'!$B:$B,A4,'03_筛查输出模板'!$M:$M,"Y")+COUNTIFS('03_筛查输出模板'!$B:$B,A4,'03_筛查输出模板'!$M:$M,"MAYBE") | J4: =IF(OR(E4>0,H4>0),"Prohibited hit present",IF(F4>0,"Restricted review needed",IF(I4>0,"Manual review needed","No flagged hits yet"))) | K4: =IF(OR(E4>0,H4>0),"Escalate immediately",IF(F4>0,"Check body site / max conc. / warnings",IF(I4>0,"Resolve fuzzy match / naming","Proceed with routine review")))

Sheet 05_模糊匹配日志
A1: Record ID | B1: Formula Code | C1: Raw INCI Name | D1: Raw CAS No | E1: Candidate Rank | F1: Candidate Ingredient | G1: Candidate Source DB | H1: Candidate CAS | I1: Similarity Score | J1: Why Suggested | K1: Final Selected? | L1: Reviewer Note

Sheet 99_下拉选项
A1: YesNo | B1: YesNoMaybe | C1: MatchMethod | D1: FinalDisposition | E1: CIRFinding
A2: Y | B2: Y | C2: Exact | D2: Pass | E2: S
A3: N | B3: N | C3: Normalized Exact | D3: Fail | E3: SQ
B4: MAYBE | C4: Alias | D4: Pending Review | E4: I
C5: Fuzzy High | D5: Need Client Clarification | E5: U
C6: Fuzzy Medium | E6: NA
C7: Fuzzy Low
C8: Manual
